<mujoco model="wx250s">
    <compiler autolimits="true" angle="radian" meshdir="models/" texturedir="images/" />
    <size njmax="500" nconmax="100" />
    <asset>
        <mesh name="WXSA-250-M-1-Base" file="WXSA-250-M-1-Base.stl" scale="0.001 0.001 0.001" />
        <mesh name="WXSA-250-M-2-Shoulder" file="WXSA-250-M-2-Shoulder.stl" scale="0.001 0.001 0.001" />
        <mesh name="WXSA-250-M-3-UA" file="WXSA-250-M-3-UA.stl" scale="0.001 0.001 0.001" />
        <mesh name="WXSA-250-M-4-UF" file="WXSA-250-M-4-UF.stl" scale="0.001 0.001 0.001" />
        <mesh name="WXSA-250-M-5-LF" file="WXSA-250-M-5-LF.stl" scale="0.001 0.001 0.001" />
        <mesh name="WXSA-250-M-6-Wrist" file="WXSA-250-M-6-Wrist.stl" scale="0.001 0.001 0.001" />
        <mesh name="WXSA-250-M-7-Gripper" file="WXSA-250-M-7-Gripper.stl" scale="0.001 0.001 0.001" />
        <texture name="texture" type="2d" file="interbotix_black.png" />
        <texture name="skybox" type="skybox" builtin="gradient" rgb1=".4 .6 .8" rgb2="0 0 0" width="800" height="800" mark="random" markrgb="1 1 1" />
        <material name="mat_texture" texture="texture" />
        <material name="black" rgba="0.15 0.15 0.15 1.0" />
        <material name="red" rgba="0.15 0.15 0.15 1.0" />
        <material name="grey" rgba="0.15 0.15 0.15 1.0" />
    </asset>
    <default>
        <default class="translation">
            <velocity kv="200" ctrlrange="-0.2 0.2" forcelimited="true" forcerange="-10 10"/>
        </default>
        <default class="rotation">
            <position kp="10" ctrlrange="-3 3" forcelimited="true" forcerange="-1 1"/>
        </default>
        <joint frictionloss='0.01' damping='2' />
        <geom solref="0.002 1" solimp="0.95 0.99 0.001" conaffinity="1" rgba="0.15 0.15 0.15 1" friction="1.0 0.01 0.0001" contype="1" condim="6" />
    </default>
    <worldbody>
        <body name="base" pos="0 0 0">
            <site name="base_site" quat="0.5 -0.5 0.5 0.5"/>
            <inertial pos="-0.0380446 0.000613892 0.0193354" quat="0.00425924 0.698088 -0.00386945 0.715989" mass="0.538736" diaginertia="0.00252518 0.00211519 0.000690737" />
            <geom quat="0.707107 0 0 0.707107" type="mesh" contype="0" conaffinity="0" group="1" density="0" mesh="WXSA-250-M-1-Base" />
            <geom quat="0.707107 0 0 0.707107" type="mesh" mesh="WXSA-250-M-1-Base" />
            <body name="shoulder_link" pos="0 0 0.072">
                <inertial pos="2.23482e-05 4.14609e-05 0.0066287" quat="-0.491122 0.490302 0.508681 0.509556" mass="0.480879" diaginertia="0.000588946 0.000555655 0.000378999" />
                <joint name="waist" pos="0 0 0" axis="0 0 1" limited="true" range="-3.14158 3.14158" />
                <geom pos="0 0 -0.003" quat="0.707107 0 0 0.707107" type="mesh" contype="0" conaffinity="0" group="1" density="0" mesh="WXSA-250-M-2-Shoulder" />
                <geom pos="0 0 -0.003" quat="0.707107 0 0 0.707107" type="mesh" mesh="WXSA-250-M-2-Shoulder" />
                <body name="upper_arm_link" pos="0 0 0.03865">
                    <inertial pos="0.0171605 2.725e-07 0.191323" quat="0 0.0665624 0 0.997782" mass="0.430811" diaginertia="0.00364425 0.003463 0.000399348" />
                    <joint name="shoulder" pos="0 0 0" axis="0 1 0" limited="true" range="-1.88496 1.98968" />
                    <geom quat="0.707107 0 0 0.707107" type="mesh" contype="0" conaffinity="0" group="1" density="0" mesh="WXSA-250-M-3-UA" />
                    <geom quat="0.707107 0 0 0.707107" type="mesh" mesh="WXSA-250-M-3-UA" />
                    <body name="upper_forearm_link" pos="0.04975 0 0.25">
                        <inertial pos="0.107963 0.000115876 0" quat="0.000980829 0.707106 -0.000980829 0.707106" mass="0.234589" diaginertia="0.000888 0.000887807 3.97035e-05" />
                        <joint name="elbow" pos="0 0 0" axis="0 1 0" limited="true" range="-2.14675 1.6057" />
                        <geom type="mesh" contype="0" conaffinity="0" group="1" density="0" mesh="WXSA-250-M-4-UF" />
                        <geom type="mesh" mesh="WXSA-250-M-4-UF" />
                        <body name="lower_forearm_link" pos="0.175 0 0">
                            <inertial pos="0.0374395 0.00522252 0" quat="-0.703302 -0.0732511 -0.703302 0.0732511" mass="0.220991" diaginertia="0.0001834 0.000172527 5.88633e-05" />
                            <joint name="forearm_roll" pos="0 0 0" axis="1 0 0" limited="true" range="-3.14158 3.14158" />
                            <geom quat="0 1 0 0" type="mesh" contype="0" conaffinity="0" group="1" density="0" mesh="WXSA-250-M-5-LF" />
                            <geom quat="0 1 0 0" type="mesh" mesh="WXSA-250-M-5-LF" />
                            <body name="wrist_link" pos="0.075 0 0">
                                <inertial pos="0.04236 -1.0663e-05 0.010577" quat="0.00129144 0.511007 0.00305617 0.85957" mass="0.084957" diaginertia="3.29057e-05 3.082e-05 2.68343e-05" />
                                <joint name="wrist_angle" pos="0 0 0" axis="0 1 0" limited="true" range="-1.74533 2.14675" />
                                <geom quat="0.707107 0 0 0.707107" type="mesh" contype="0" conaffinity="0" group="1" density="0" mesh="WXSA-250-M-6-Wrist" />
                                <geom quat="0.707107 0 0 0.707107" type="mesh" mesh="WXSA-250-M-6-Wrist" />
                                <body name="gripper_link" pos="0.065 0 0">
                                    <inertial pos="0.021631 2.516e-07 0.01141" quat="0.701767 0.0867335 0.0867335 0.701767" mass="0.072885" diaginertia="2.537e-05 1.84689e-05 1.66311e-05" />
                                    <joint name="wrist_rotate" pos="0 0 0" axis="1 0 0" limited="true" range="-3.14158 3.14158" />
                                    <geom pos="-0.02 0 0" quat="0.707107 0 0 0.707107" type="mesh" contype="0" conaffinity="0" group="1" density="0" mesh="WXSA-250-M-7-Gripper" />
                                    <geom pos="-0.02 0 0" quat="0.707107 0 0 0.707107" type="mesh" mesh="WXSA-250-M-7-Gripper" />
                                    <site name="wrist_site" />
                                </body>
                            </body>
                        </body>
                    </body>
                </body>
            </body>
            <body name="camera_target" pos="0.0 0.0 0.0"/>
        </body>
        <camera name="pixels" mode="targetbody" target="camera_target" pos="0.25 0.75 0.25" fovy="45" />
    </worldbody>
    <actuator>
        <velocity name="x" site="wrist_site" refsite="base_site" gear="1 0 0 0 0 0" class="translation" />
        <velocity name="y" site="wrist_site" refsite="base_site" gear="0 1 0 0 0 0" class="translation" />
        <velocity name="z" site="wrist_site" refsite="base_site" gear="0 0 1 0 0 0" class="translation" />
        <position name="rx" site="wrist_site" refsite="base_site" gear="0 0 0 1 0 0" class="rotation" />
        <position name="ry" site="wrist_site" refsite="base_site" gear="0 0 0 0 1 0" class="rotation" />
        <position name="rz" site="wrist_site" refsite="base_site" gear="0 0 0 0 0 1" class="rotation" />
    </actuator>
    <contact>
        <exclude body1='base' body2='shoulder_link' />
        <exclude body1='shoulder_link' body2='upper_arm_link' />
        <exclude body1='upper_arm_link' body2='upper_forearm_link' />
        <exclude body1='upper_forearm_link' body2='lower_forearm_link' />
        <exclude body1='lower_forearm_link' body2='wrist_link' />
        <exclude body1='wrist_link' body2='gripper_link' />
    </contact>
</mujoco>