<!--Copyright 2020 Google LLC-->

<!--Licensed under the Apache License, Version 2.0 (the "License");-->
<!--you may not use this file except in compliance with the License.-->
<!--You may obtain a copy of the License at-->

    <!--https://www.apache.org/licenses/LICENSE-2.0-->

<!--Unless required by applicable law or agreed to in writing, software-->
<!--distributed under the License is distributed on an "AS IS" BASIS,-->
<!--WITHOUT WARRANTIES OR CONDITIONS OF ANY KIND, either express or implied.-->
<!--See the License for the specific language governing permissions and-->
<!--limitations under the License.-->

<mujoco model="franka_mocap_studyTable_buttons">

    <size njmax='1000' nconmax='1000'/>

    <include file="../../../../adept_models/scenes/basic_scene.xml"/>
    <include file="../../../../third_party/franka/assets/assets.xml"/>
    <include file="../../../../third_party/franka/assets/actuator0.xml"/>
    <include file="../../../../adept_models/kitchen/assets/oven_asset.xml"/>
    <include file="../../../../adept_models/kitchen/assets/counters_asset.xml"/>
    <include file="../../../../adept_models/kitchen/assets/backwall_asset.xml"/>
    <include file="../../../../adept_models/kitchen/assets/slidecabinet_asset.xml"/>
    <include file="../../../../adept_models/kitchen/assets/hingecabinet_asset.xml"/>
    <include file="../../../../adept_models/kitchen/assets/microwave_asset.xml"/>
    <include file="../../../../adept_models/kitchen/assets/kettle_asset.xml"/>

    <visual>
    <global offwidth="2560" offheight="1920" />
    <quality shadowsize="4096" offsamples="8" />
    <map force="0.1" fogend="5" />
    </visual>

    <compiler inertiafromgeom='auto' inertiagrouprange='3 5' angle="radian"
              meshdir="../../../../adept_models/kitchen"
              texturedir="../../../../adept_models/kitchen"/>

    <equality>
        <weld body1="vive_controller" body2="world" solref="0.02 1" solimp=".7 .95 0.050"/>
    </equality>

    <worldbody>

        <!-- Mocap -->
        <body name="vive_controller" mocap="true" pos="-0.440 -0.092 2.026" euler="-1.57 0 -.785">
            <geom type="box" group="2" pos='0 0 .142' size="0.02 0.10 0.03" contype="0" conaffinity="0" rgba=".9 .7 .95 0" euler="0 0 -.785"/>
        </body>

        <site name='target' pos='0 0 0' size='0.1' rgba='0 2 0 .2'/>
        <camera name='left_cap' pos='-1.2 -0.5 1.8' quat='0.78 0.49 -0.22 -0.32' />
        <camera name='right_cap' pos='1.2 -0.5 1.8' quat='0.76 0.5 0.21 0.35'/>

        <!-- Robot -->
        <body pos='0. 0 1.8' euler='0 0 1.57'>
            <geom type='cylinder' size='.120 .90' pos='-.04 0 -0.90' class='panda_viz'/>
            <include file="../../../../third_party/franka/assets/chain0.xml"/>
        </body>

        <body name='desk' pos='-0.1 0.75 0'>

            <body name="counters1" pos="0 0 0" >
                <include file="../../../../adept_models/kitchen/assets/counters_chain.xml"/>
            </body>
            <body name="oven" pos="0 0 0" >
                <include file="../../../../adept_models/kitchen/assets/oven_chain.xml"/>
            </body>
            <body name="backwall" pos="0 0 0" >
                <include file="../../../../adept_models/kitchen/assets/backwall_chain.xml"/>
            </body>
            <body name="slidecabinet" pos="0.4 0.3 2.6" >
                <include file="../../../../adept_models/kitchen/assets/slidecabinet_chain.xml"/>
            </body>
            <body name="hingecabinet" pos="-0.504 0.28 2.6" >
                <include file="../../../../adept_models/kitchen/assets/hingecabinet_chain.xml"/>
            </body>
            <body name="microwave" pos="-0.750 -0.025 1.6" euler="0 0 0.3">
                <include file="../../../../adept_models/kitchen/assets/microwave_chain.xml"/>
            </body>
        </body>
        <body name="kettle" pos="-0.269 0.35 1.626">
            <freejoint/>
            <include file="../../../../adept_models/kitchen/assets/kettle_chain.xml"/>
        </body>


        <body name="panda0_link0" childclass="panda">
            <geom class="panda_viz" type="mesh" mesh="link0_viz"/>
            <geom class="panda_col" type="mesh" mesh="link0_col" mass="2.91242"/>
            <body name="panda0_link1" pos="0 0 0.333">
                <joint type="hinge" name="panda0_joint1" range="-2.8973 2.8973" class="panda_arm"/>
                <geom class="panda_viz" type="mesh" mesh="link1_viz"/>
                <geom class="panda_col" type="mesh" mesh="link1_col" mass="2.7063"/>
                <body name="panda0_link2" pos="0 0 0" quat="0.707107 -0.707107 0 0">
                    <joint type="hinge" name="panda0_joint2" range="-1.7628 1.7628" class="panda_arm"/>
                    <geom class="panda_viz" type="mesh" mesh="link2_viz"/>
                    <geom class="panda_col" type="mesh" mesh="link2_col" mass="2.73046"/>
                    <body name="panda0_link3" pos="0 -0.316 0" quat="0.707107 0.707107 0 0">
                        <joint type="hinge" name="panda0_joint3" range="-2.8973 2.8973" class="panda_arm"/>
                        <geom class="panda_viz" type="mesh" mesh="link3_viz"/>
                        <geom class="panda_col" type="mesh" mesh="link3_col" mass="2.04104"/>
                        <body name="panda0_link4" pos="0.0825 0 0" quat="0.707107 0.707107 0 0">
                            <joint type="hinge" name="panda0_joint4" range="-3.0718 -0.0698" class="panda_arm"/>
                            <geom class="panda_viz" type="mesh" mesh="link4_viz"/>
                            <geom class="panda_col" type="mesh" mesh="link4_col" mass="2.08129"/>
                            <body name="panda0_link5" pos="-0.0825 0.384 0" quat="0.707107 -0.707107 0 0">
                                <joint type="hinge" name="panda0_joint5" range="-2.8973 2.8973" class="panda_forearm"/>
                                <geom class="panda_viz" type="mesh" mesh="link5_viz"/>
                                <geom class="panda_col" type="mesh" mesh="link5_col" mass="3.00049"/>
                                <body name="panda0_link6" pos="0 0 0" euler="1.57 0 1.57">
                                    <joint type="hinge" name="panda0_joint6" range="-0.0175 3.7525" class="panda_forearm"/>
                                    <geom class="panda_viz" type="mesh" mesh="link6_viz"/>
                                    <geom class="panda_col" type="mesh" mesh="link6_col" mass="1.3235"/>
                                    <body name="panda0_link7" pos="0.088 0 0" euler="1.57 0 0.7854">
                                        <joint type="hinge" name="panda0_joint7" range="-2.8973 2.8973" class="panda_forearm"/>
                                        <geom class="panda_viz" type="mesh" mesh="link7_viz"/>
                                        <geom class="panda_col" type="mesh" mesh="link7_col" mass="0.2"/>
                                        <geom pos="0 0 0.107" quat="0.92388 0 0 -0.382683" class="panda_viz" type="mesh" mesh="hand_viz"/>
                                        <geom pos="0 0 0.107" quat="0.92388 0 0 -0.382683" class="panda_col" type="mesh" mesh="hand_col" mass="0.81909"/>
                                        <camera euler="2.792526 0.3490658 -0.755398" fovy="50" name="gripper_camera_rgb" pos="0.15 -0.15 0."></camera>
                                        <site name="end_effector" pos="0 0 .210" size="0.01" euler="0 0 -0.785398" rgba="1 0 0 0"/>
                                        <body name="panda0_leftfinger" pos="0 0 0.1654" quat="0.92388 0 0 -0.382683" childclass="panda_finger">
                                            <inertial pos="-1.57863e-05 0.0118731 0.0434103" quat="0.705868 0.0310348 -0.0314925 0.706962" mass="0.0927059" diaginertia="6.57134e-05 6.09611e-05 1.09932e-05"/>
                                            <joint name="panda0_finger_joint1" axis="0 1 0" type="slide" range="0 0.04" class="panda_finger"/>
                                            <geom class="panda_viz" type="mesh" mesh="finger_viz"/>
                                            <!-- <geom class="panda_col" type="mesh" mesh="finger_col"/> -->

                                            <geom size="0.0070" fromto=".009 .006 .0875 -.009 .009 .0875" type="capsule"/>
                                            <geom size="0.0070" fromto=".009 .009 .0875 -.009 .006 .0875" type="capsule"/>
                                            <geom size="0.0075" fromto=".009 .007 .0775 -.009 .010 .0775" type="capsule"/>
                                            <geom size="0.0075" fromto=".009 .010 .0775 -.009 .007 .0775" type="capsule"/>
                                            <geom size="0.0082" fromto=".009 .008 .0675 -.009 .011 .0675" type="capsule"/>
                                            <geom size="0.0082" fromto=".009 .011 .0675 -.009 .008 .0675" type="capsule"/>
                                            <geom size="0.0090" fromto=".009 .009 .0575 -.009 .012 .0575" type="capsule"/>
                                            <geom size="0.0090" fromto=".009 .012 .0575 -.009 .009 .0575" type="capsule"/>
                                            <geom size="0.0100" fromto=".009 .0105 .0475 -.009 .0135 .0475" type="capsule"/>
                                            <geom size="0.0100" fromto=".009 .0135 .0475 -.009 .0105 .0475" type="capsule"/>
                                            <geom size="0.0110" fromto=".009 .012 .035 -.009 .015 .035" type="capsule"/>
                                            <geom size="0.0110" fromto=".009 .015 .035 -.009 .012 .035" type="capsule"/>
                                            <geom size="0.0185 0.0120 0.0175" pos="0 0.014 0.015" type="box" euler=".03 0 0"/>
                                        </body>
                                        <body name="panda0_rightfinger" pos="0 0 0.1654" quat="0.92388 0 0 -0.382683" childclass="panda_finger">
                                            <inertial pos="1.57863e-05 -0.0118731 0.0434103" quat="0.705868 -0.0310348 0.0314925 0.706962" mass="0.0927059" diaginertia="6.57134e-05 6.09611e-05 1.09932e-05"/>
                                            <joint name="panda0_finger_joint2" axis="0 -1 0" type="slide" range="0 0.04" class="panda_finger"/>
                                            <geom quat="0 0 0 1" class="panda_viz" type="mesh" mesh="finger_viz"/>
                                            <!-- <geom quat="0 0 0 1" class="panda_col" type="mesh" mesh="finger_col"/> -->

                                            <geom size="0.0070" fromto=".009 -.006 .0875 -.009 -.009 .0875" type="capsule"/>
                                            <geom size="0.0070" fromto=".009 -.009 .0875 -.009 -.006 .0875" type="capsule"/>
                                            <geom size="0.0075" fromto=".009 -.007 .0775 -.009 -.010 .0775" type="capsule"/>
                                            <geom size="0.0075" fromto=".009 -.010 .0775 -.009 -.007 .0775" type="capsule"/>
                                            <geom size="0.0082" fromto=".009 -.008 .0675 -.009 -.011 .0675" type="capsule"/>
                                            <geom size="0.0082" fromto=".009 -.011 .0675 -.009 -.008 .0675" type="capsule"/>
                                            <geom size="0.0090" fromto=".009 -.009 .0575 -.009 -.012 .0575" type="capsule"/>
                                            <geom size="0.0090" fromto=".009 -.012 .0575 -.009 -.009 .0575" type="capsule"/>
                                            <geom size="0.0100" fromto=".009 -.0105 .0475 -.009 -.0135 .0475" type="capsule"/>
                                            <geom size="0.0100" fromto=".009 -.0135 .0475 -.009 -.0105 .0475" type="capsule"/>
                                            <geom size="0.0110" fromto=".009 -.012 .035 -.009 -.015 .035" type="capsule"/>
                                            <geom size="0.0110" fromto=".009 -.015 .035 -.009 -.012 .035" type="capsule"/>
                                            <geom size="0.0185 0.0120 0.0175" pos="0 -.014 0.015" type="box" euler="-.03 0 0"/>
                                        </body>
                                    </body>
                                </body>
                            </body>
                        </body>
                    </body>
                </body>
            </body>
        </body>

    </worldbody>


    <keyframe>
        <key qpos='0.16 -1.76 1.84 -2.51 0.36 0.79 1.55 0.00 0.0 1.25561e-05 1.57437e-07 1.25561e-05 1.57437e-07 1.25561e-05 1.57437e-07 1.25561e-05 1.57437e-07 8.24417e-05 9.48283e-05 0 0 0 0 -0.269 0.35 1.61523 1 1.34939e-19 -3.51612e-05 -7.50168e-19'/>
    </keyframe>

</mujoco>
