<?xml version="1.0" ?>
<robot name="partnet_367cf1804054c94c297c85b9a7ad9cde">
	<link name="base"/>
	<link name="link_0">
		<visual name="switch-1">
			<origin xyz="-0.6004359999999993 -0.05795399702183715 0.21110114892914889"/>
			<geometry>
				<mesh filename="textured_objs/original-1.obj"/>
			</geometry>
		</visual>
		<collision>
			<origin xyz="-0.6004359999999993 -0.05795399702183715 0.21110114892914889"/>
			<geometry>
				<mesh filename="textured_objs/original-1.obj"/>
			</geometry>
		</collision>
	</link>
	<joint name="joint_0" type="revolute">
		<origin xyz="0.6004359999999993 0.05795399702183715 -0.21110114892914889"/>
		<axis xyz="-1 0 0"/>
		<child link="link_0"/>
		<parent link="link_4"/>
		<limit lower="-0.8293804605477054" upper="1.426283064729766"/>
	</joint>
	<link name="link_1">
		<visual name="switch-2">
			<origin xyz="-0.6004359999999993 -0.05795399702183715 0.21110114892914889"/>
			<geometry>
				<mesh filename="textured_objs/original-2.obj"/>
			</geometry>
		</visual>
		<collision>
			<origin xyz="-0.6004359999999993 -0.05795399702183715 0.21110114892914889"/>
			<geometry>
				<mesh filename="textured_objs/original-2.obj"/>
			</geometry>
		</collision>
	</link>
	<joint name="joint_1" type="revolute">
		<origin xyz="0.6004359999999993 0.05795399702183715 -0.21110114892914889"/>
		<axis xyz="-1 0 0"/>
		<child link="link_1"/>
		<parent link="link_4"/>
		<limit lower="-0.8293804605477054" upper="1.426283064729766"/>
	</joint>
	<link name="link_2">
		<visual name="switch-3">
			<origin xyz="-0.6004359999999993 -0.05795399702183715 0.21110114892914889"/>
			<geometry>
				<mesh filename="textured_objs/original-3.obj"/>
			</geometry>
		</visual>
		<collision>
			<origin xyz="-0.6004359999999993 -0.05795399702183715 0.21110114892914889"/>
			<geometry>
				<mesh filename="textured_objs/original-3.obj"/>
			</geometry>
		</collision>
	</link>
	<joint name="joint_2" type="revolute">
		<origin xyz="0.6004359999999993 0.05795399702183715 -0.21110114892914889"/>
		<axis xyz="-1 0 0"/>
		<child link="link_2"/>
		<parent link="link_4"/>
		<limit lower="-0.8293804605477054" upper="1.426283064729766"/>
	</joint>
	<link name="link_3">
		<visual name="switch-4">
			<origin xyz="-0.6004359999999993 -0.05795399702183715 0.21110114892914889"/>
			<geometry>
				<mesh filename="textured_objs/original-4.obj"/>
			</geometry>
		</visual>
		<collision>
			<origin xyz="-0.6004359999999993 -0.05795399702183715 0.21110114892914889"/>
			<geometry>
				<mesh filename="textured_objs/original-4.obj"/>
			</geometry>
		</collision>
	</link>
	<joint name="joint_3" type="revolute">
		<origin xyz="0.6004359999999993 0.05795399702183715 -0.21110114892914889"/>
		<axis xyz="-1 0 0"/>
		<child link="link_3"/>
		<parent link="link_4"/>
		<limit lower="-0.8293804605477054" upper="1.426283064729766"/>
	</joint>
	<link name="link_4">
		<visual name="base_body-5">
			<origin xyz="0 0 0"/>
			<geometry>
				<mesh filename="textured_objs/original-5.obj"/>
			</geometry>
		</visual>
		<collision>
			<origin xyz="0 0 0"/>
			<geometry>
				<mesh filename="textured_objs/original-5.obj"/>
			</geometry>
		</collision>
	</link>
	<joint name="joint_4" type="fixed">
		<origin rpy="1.570796326794897 0 -1.570796326794897" xyz="0 0 0"/>
		<child link="link_4"/>
		<parent link="base"/>
	</joint>
</robot>
